[2024-10-28T16:26:49.570+0000] {taskinstance.py:1083} INFO - Dependencies all met for <TaskInstance: create_bronze_ddl.create_schema manual__2024-10-28T16:26:48.650448+00:00 [queued]>
[2024-10-28T16:26:49.589+0000] {taskinstance.py:1083} INFO - Dependencies all met for <TaskInstance: create_bronze_ddl.create_schema manual__2024-10-28T16:26:48.650448+00:00 [queued]>
[2024-10-28T16:26:49.589+0000] {taskinstance.py:1279} INFO - 
--------------------------------------------------------------------------------
[2024-10-28T16:26:49.589+0000] {taskinstance.py:1280} INFO - Starting attempt 1 of 2
[2024-10-28T16:26:49.590+0000] {taskinstance.py:1281} INFO - 
--------------------------------------------------------------------------------
[2024-10-28T16:26:49.618+0000] {taskinstance.py:1300} INFO - Executing <Task(PostgresOperator): create_schema> on 2024-10-28 16:26:48.650448+00:00
[2024-10-28T16:26:49.625+0000] {standard_task_runner.py:55} INFO - Started process 2989 to run task
[2024-10-28T16:26:49.628+0000] {standard_task_runner.py:82} INFO - Running: ['***', 'tasks', 'run', 'create_bronze_ddl', 'create_schema', 'manual__2024-10-28T16:26:48.650448+00:00', '--job-id', '18', '--raw', '--subdir', 'DAGS_FOLDER/create_bronze_ddl.py', '--cfg-path', '/tmp/tmp6ogsng_n']
[2024-10-28T16:26:49.629+0000] {standard_task_runner.py:83} INFO - Job 18: Subtask create_schema
[2024-10-28T16:26:49.690+0000] {task_command.py:388} INFO - Running <TaskInstance: create_bronze_ddl.create_schema manual__2024-10-28T16:26:48.650448+00:00 [running]> on host 351cc7a93433
[2024-10-28T16:26:49.753+0000] {taskinstance.py:1509} INFO - Exporting the following env vars:
AIRFLOW_CTX_DAG_EMAIL=anduy@localmail.com
AIRFLOW_CTX_DAG_OWNER=anduy
AIRFLOW_CTX_DAG_ID=create_bronze_ddl
AIRFLOW_CTX_TASK_ID=create_schema
AIRFLOW_CTX_EXECUTION_DATE=2024-10-28T16:26:48.650448+00:00
AIRFLOW_CTX_TRY_NUMBER=1
AIRFLOW_CTX_DAG_RUN_ID=manual__2024-10-28T16:26:48.650448+00:00
[2024-10-28T16:26:49.753+0000] {sql.py:254} INFO - Executing: CREATE SCHEMA IF NOT EXISTS bronze;
[2024-10-28T16:26:49.772+0000] {taskinstance.py:1768} ERROR - Task failed with exception
Traceback (most recent call last):
  File "/home/airflow/.local/lib/python3.7/site-packages/airflow/providers/common/sql/operators/sql.py", line 255, in execute
    hook = self.get_db_hook()
  File "/home/airflow/.local/lib/python3.7/site-packages/airflow/providers/common/sql/operators/sql.py", line 179, in get_db_hook
    return self._hook
  File "/home/airflow/.local/lib/python3.7/site-packages/cached_property.py", line 36, in __get__
    value = obj.__dict__[self.func.__name__] = self.func(obj)
  File "/home/airflow/.local/lib/python3.7/site-packages/airflow/providers/common/sql/operators/sql.py", line 141, in _hook
    conn = BaseHook.get_connection(self.conn_id)
  File "/home/airflow/.local/lib/python3.7/site-packages/airflow/hooks/base.py", line 72, in get_connection
    conn = Connection.get_connection_from_secrets(conn_id)
  File "/home/airflow/.local/lib/python3.7/site-packages/airflow/models/connection.py", line 435, in get_connection_from_secrets
    raise AirflowNotFoundException(f"The conn_id `{conn_id}` isn't defined")
airflow.exceptions.AirflowNotFoundException: The conn_id `postgres_default` isn't defined
[2024-10-28T16:26:49.776+0000] {taskinstance.py:1323} INFO - Marking task as UP_FOR_RETRY. dag_id=create_bronze_ddl, task_id=create_schema, execution_date=20241028T162648, start_date=20241028T162649, end_date=20241028T162649
[2024-10-28T16:26:49.789+0000] {warnings.py:110} WARNING - /home/***/.local/lib/python3.7/site-packages/***/utils/email.py:152: RemovedInAirflow3Warning: Fetching SMTP credentials from configuration variables will be deprecated in a future release. Please set credentials using a connection instead.
  send_mime_email(e_from=mail_from, e_to=recipients, mime_msg=msg, conn_id=conn_id, dryrun=dryrun)

[2024-10-28T16:26:49.789+0000] {configuration.py:663} WARNING - section/key [smtp/smtp_user] not found in config
[2024-10-28T16:26:49.790+0000] {email.py:268} INFO - Email alerting: attempt 1
[2024-10-28T16:26:49.799+0000] {configuration.py:663} WARNING - section/key [smtp/smtp_user] not found in config
[2024-10-28T16:26:49.800+0000] {email.py:268} INFO - Email alerting: attempt 1
[2024-10-28T16:26:49.801+0000] {taskinstance.py:1831} ERROR - Failed to send email to: ['anduy@localmail.com']
Traceback (most recent call last):
  File "/home/airflow/.local/lib/python3.7/site-packages/airflow/models/taskinstance.py", line 1374, in _run_raw_task
    self._execute_task_with_callbacks(context, test_mode)
  File "/home/airflow/.local/lib/python3.7/site-packages/airflow/models/taskinstance.py", line 1520, in _execute_task_with_callbacks
    result = self._execute_task(context, task_orig)
  File "/home/airflow/.local/lib/python3.7/site-packages/airflow/models/taskinstance.py", line 1581, in _execute_task
    result = execute_callable(context=context)
  File "/home/airflow/.local/lib/python3.7/site-packages/airflow/providers/common/sql/operators/sql.py", line 255, in execute
    hook = self.get_db_hook()
  File "/home/airflow/.local/lib/python3.7/site-packages/airflow/providers/common/sql/operators/sql.py", line 179, in get_db_hook
    return self._hook
  File "/home/airflow/.local/lib/python3.7/site-packages/cached_property.py", line 36, in __get__
    value = obj.__dict__[self.func.__name__] = self.func(obj)
  File "/home/airflow/.local/lib/python3.7/site-packages/airflow/providers/common/sql/operators/sql.py", line 141, in _hook
    conn = BaseHook.get_connection(self.conn_id)
  File "/home/airflow/.local/lib/python3.7/site-packages/airflow/hooks/base.py", line 72, in get_connection
    conn = Connection.get_connection_from_secrets(conn_id)
  File "/home/airflow/.local/lib/python3.7/site-packages/airflow/models/connection.py", line 435, in get_connection_from_secrets
    raise AirflowNotFoundException(f"The conn_id `{conn_id}` isn't defined")
airflow.exceptions.AirflowNotFoundException: The conn_id `postgres_default` isn't defined

During handling of the above exception, another exception occurred:

Traceback (most recent call last):
  File "/home/airflow/.local/lib/python3.7/site-packages/airflow/models/taskinstance.py", line 2231, in email_alert
    send_email(task.email, subject, html_content)
  File "/home/airflow/.local/lib/python3.7/site-packages/airflow/utils/email.py", line 91, in send_email
    **kwargs,
  File "/home/airflow/.local/lib/python3.7/site-packages/airflow/utils/email.py", line 152, in send_email_smtp
    send_mime_email(e_from=mail_from, e_to=recipients, mime_msg=msg, conn_id=conn_id, dryrun=dryrun)
  File "/home/airflow/.local/lib/python3.7/site-packages/airflow/utils/email.py", line 270, in send_mime_email
    smtp_conn = _get_smtp_connection(smtp_host, smtp_port, smtp_timeout, smtp_ssl)
  File "/home/airflow/.local/lib/python3.7/site-packages/airflow/utils/email.py", line 317, in _get_smtp_connection
    else smtplib.SMTP(host=host, port=port, timeout=timeout)
  File "/usr/local/lib/python3.7/smtplib.py", line 251, in __init__
    (code, msg) = self.connect(host, port)
  File "/usr/local/lib/python3.7/smtplib.py", line 336, in connect
    self.sock = self._get_socket(host, port, self.timeout)
  File "/usr/local/lib/python3.7/smtplib.py", line 307, in _get_socket
    self.source_address)
  File "/usr/local/lib/python3.7/socket.py", line 728, in create_connection
    raise err
  File "/usr/local/lib/python3.7/socket.py", line 716, in create_connection
    sock.connect(sa)
ConnectionRefusedError: [Errno 111] Connection refused

During handling of the above exception, another exception occurred:

Traceback (most recent call last):
  File "/home/airflow/.local/lib/python3.7/site-packages/airflow/models/taskinstance.py", line 1829, in handle_failure
    self.email_alert(error, task)
  File "/home/airflow/.local/lib/python3.7/site-packages/airflow/models/taskinstance.py", line 2233, in email_alert
    send_email(task.email, subject, html_content_err)
  File "/home/airflow/.local/lib/python3.7/site-packages/airflow/utils/email.py", line 91, in send_email
    **kwargs,
  File "/home/airflow/.local/lib/python3.7/site-packages/airflow/utils/email.py", line 152, in send_email_smtp
    send_mime_email(e_from=mail_from, e_to=recipients, mime_msg=msg, conn_id=conn_id, dryrun=dryrun)
  File "/home/airflow/.local/lib/python3.7/site-packages/airflow/utils/email.py", line 270, in send_mime_email
    smtp_conn = _get_smtp_connection(smtp_host, smtp_port, smtp_timeout, smtp_ssl)
  File "/home/airflow/.local/lib/python3.7/site-packages/airflow/utils/email.py", line 317, in _get_smtp_connection
    else smtplib.SMTP(host=host, port=port, timeout=timeout)
  File "/usr/local/lib/python3.7/smtplib.py", line 251, in __init__
    (code, msg) = self.connect(host, port)
  File "/usr/local/lib/python3.7/smtplib.py", line 336, in connect
    self.sock = self._get_socket(host, port, self.timeout)
  File "/usr/local/lib/python3.7/smtplib.py", line 307, in _get_socket
    self.source_address)
  File "/usr/local/lib/python3.7/socket.py", line 728, in create_connection
    raise err
  File "/usr/local/lib/python3.7/socket.py", line 716, in create_connection
    sock.connect(sa)
ConnectionRefusedError: [Errno 111] Connection refused
[2024-10-28T16:26:49.815+0000] {standard_task_runner.py:105} ERROR - Failed to execute job 18 for task create_schema (The conn_id `postgres_default` isn't defined; 2989)
[2024-10-28T16:26:49.844+0000] {local_task_job.py:208} INFO - Task exited with return code 1
[2024-10-28T16:26:49.871+0000] {taskinstance.py:2578} INFO - 0 downstream tasks scheduled from follow-on schedule check
